Workbook

Sheet インプット
A1: ■ 基礎データ
A2: 資産区分 | B2: 時価(億円) | C2: 簿価(億円)
A3: 債券 | B3: 575 | C3: 516
A4: 株式 | B4: 125 | C4: 119
A5: プライベート | B5: 70 | C5: 70
A7: ■ 目標構成比
A8: 資産区分 | B8: 下限 | C8: 中央 | D8: 上限
A9: 伝統資産うち債券 | B9: 0.4 | C9: 0.45 | D9: 0.5
A10: 伝統資産うち株式 | B10: 0.2 | C10: 0.25 | D10: 0.3
A11: プライベート資産 | B11: 0.2 | C11: 0.25 | D11: 0.3
A13: ■ 償還スケジュール(億円・簿価ベース)
A14: 資産区分 | B14: 2026 | C14: 2027 | D14: 2028 | E14: 2029 | F14: 2030
A15: 債券 | B15: 33 | C15: 42 | D15: 31 | E15: 64.5 | F15: 59
A16: 株式 | B16: 20 | C16: 0 | D16: 0 | E16: 0 | F16: 0
A18: ■ 投資額(億円)
A19: 項目 | B19: 2026 | C19: 2027 | D19: 2028 | E19: 2029 | F19: 2030
A20: 伝統資産 | B20: 30 | C20: 15 | D20: 10 | E20: 34 | F20: 15
A21: プライベート | B21: 11.6 | C21: 9.2 | D21: 5.2 | E21: 3 | F21: 1.6
A23: ■ パラメータ（数式で使用・変更可能）
A24: ← オレンジ枠の値を変更するとリターン計算に反映
A26: 項目 | B26: 値 | C26: 説明
A27: 内債デュレーション | B27: 7 | C27: 金利変動に対する価格感応度
A28: ユーロ円債デュレーション | B28: 5
A29: 外債米ドルデュレーション | B29: 6
A30: 外債豪ドルデュレーション | B30: 5.5
A31: ユーロ円債スプレッド(対JGB) | B31: 0.003 | C31: JGB利回りに加算
A32: 外債豪ドルスプレッド(対UST) | B32: 0.005
A33: 豪ドル債 金利感応度係数 | B33: 0.7 | C33: UST変動に対する豪ドル債の感応度
A35: ■ 債券ウェイト（加重平均計算用）
A36: 資産 | B36: 初期時価(億円) | C36: ウェイト
A37: 内債 | B37: 124 | C37: =B37/SUM(B37:B40) -> 0
A38: ユーロ円債 | B38: 187 | C38: =B38/SUM(B37:B40) -> 0
A39: 外債米ドル建て | B39: 158 | C39: =B39/SUM(B37:B40) -> 0
A40: 外債豪ドル建て | B40: 106 | C40: =B40/SUM(B37:B40) -> 0
A43: ■ ハウスビュー（年度末水準） — Bull(楽観)
A44: ← オレンジ枠に日興証券等のデータを入力
A46: 指標 | B46: 現在値 | C46: 2026 | D46: 2027 | E46: 2028 | F46: 2029 | G46: 2030
A47: 日本国債10年利回り(%) | B47: 1.47 | C47: 1.68 | D47: 1.5 | E47: 1.17 | F47: 1.295 | G47: 1.12
A48: 米国債10年利回り(%) | B48: 4.39 | C48: 4.7 | D48: 4.02 | E48: 2.21 | F48: 3.84 | G48: 3.29
A49: ドル/円 | B49: 118.07 | C49: 119.11 | D49: 111.71 | E49: 90.64 | F49: 93.02 | G49: 81.49
...

Sheet Bull
A1: ■ Bull(楽観) シミュレーション
A2: 配分比率(オレンジ枠)を変更可。リターンはインプットシートから自動計算。
A3: 株式配分比率 ← 変更可 | C3: 1 | D3: 1 | E3: 1 | F3: 1 | G3: 1
A4: 債券配分比率 | C4: =1-C3 -> 0 | D4: =1-D3 -> 0 | E4: =1-E3 -> 0 | F4: =1-F3 -> 0 | G4: =1-G3 -> 0
A6: 債券期待ﾘﾀｰﾝ(自動) | C6: ='インプット'!B85 -> 0 | D6: ='インプット'!C85 -> 0 | E6: ='インプット'!D85 -> 0 | F6: ='インプット'!E85 -> 0 | G6: ='インプット'!F85 -> 0
A7: 株式期待ﾘﾀｰﾝ(自動) | C7: ='インプット'!B86 -> 0 | D7: ='インプット'!C86 -> 0 | E7: ='インプット'!D86 -> 0 | F7: ='インプット'!E86 -> 0 | G7: ='インプット'!F86 -> 0
B9: 現状 | C9: 2026 | D9: 2027 | E9: 2028 | F9: 2029 | G9: 2030 | H9: 目標
A10: 債券償還(簿価) | B10: 0 | C10: ='インプット'!B15 -> 0 | D10: ='インプット'!C15 -> 0 | E10: ='インプット'!D15 -> 0 | F10: ='インプット'!E15 -> 0 | G10: ='インプット'!F15 -> 0
A11: 株式償還 | B11: 0 | C11: ='インプット'!B16 -> 0 | D11: ='インプット'!C16 -> 0 | E11: ='インプット'!D16 -> 0 | F11: ='インプット'!E16 -> 0 | G11: ='インプット'!F16 -> 0
A12: 伝統資産投資 | B12: 0 | C12: ='インプット'!B20 -> 0 | D12: ='インプット'!C20 -> 0 | E12: ='インプット'!D20 -> 0 | F12: ='インプット'!E20 -> 0 | G12: ='インプット'!F20 -> 0
A13: ﾌﾟﾗｲﾍﾞｰﾄ投資 | B13: 0 | C13: ='インプット'!B21 -> 0 | D13: ='インプット'!C21 -> 0 | E13: ='インプット'!D21 -> 0 | F13: ='インプット'!E21 -> 0 | G13: ='インプット'!F21 -> 0
A14: → 債券投資 | B14: 0 | C14: =C12*(1-C3) -> 0 | D14: =D12*(1-D3) -> 0 | E14: =E12*(1-E3) -> 0 | F14: =F12*(1-F3) -> 0 | G14: =G12*(1-G3) -> 0
A15: → 株式投資 | B15: 0 | C15: =C12*C3 -> 0 | D15: =D12*D3 -> 0 | E15: =E12*E3 -> 0 | F15: =F12*F3 -> 0 | G15: =G12*G3 -> 0
A17: 債券残高(時価) | B17: ='インプット'!B3 -> 0 | C17: =(B17-C10)*(1+C6)+C14 -> 0 | D17: =(C17-D10)*(1+D6)+D14 -> 0 | E17: =(D17-E10)*(1+E6)+E14 -> 0 | F17: =(E17-F10)*(1+F6)+F14 -> 0 | G17: =(F17-G10)*(1+G6)+G14 -> 0
A18: 株式残高(時価) | B18: ='インプット'!B4 -> 0 | C18: =(B18-C11)*(1+C7)+C15 -> 0 | D18: =(C18-D11)*(1+D7)+D15 -> 0 | E18: =(D18-E11)*(1+E7)+E15 -> 0 | F18: =(E18-F11)*(1+F7)+F15 -> 0 | G18: =(F18-G11)*(1+G7)+G15 -> 0
A19: ﾌﾟﾗｲﾍﾞｰﾄ残高 | B19: ='インプット'!B5 -> 0 | C19: =B19+C13 -> 0 | D19: =C19+D13 -> 0 | E19: =D19+E13 -> 0 | F19: =E19+F13 -> 0 | G19: =F19+G13 -> 0
A20: 合計(時価) | B20: =B17+B18+B19 -> 0 | C20: =C17+C18+C19 -> 0 | D20: =D17+D18+D19 -> 0 | E20: =E17+E18+E19 -> 0 | F20: =F17+F18+F19 -> 0 | G20: =G17+G18+G19 -> 0
A22: 債券構成比 | B22: =B17/B20 -> 0 | C22: =C17/C20 -> 0 | D22: =D17/D20 -> 0 | E22: =E17/E20 -> 0 | F22: =F17/F20 -> 0 | G22: =G17/G20 -> 0 | H22: 0.45
A23: 株式構成比 | B23: =B18/B20 -> 0 | C23: =C18/C20 -> 0 | D23: =D18/D20 -> 0 | E23: =E18/E20 -> 0 | F23: =F18/F20 -> 0 | G23: =G18/G20 -> 0 | H23: 0.25
A24: ﾌﾟﾗｲﾍﾞｰﾄ構成比 | B24: =B19/B20 -> 0 | C24: =C19/C20 -> 0 | D24: =D19/D20 -> 0 | E24: =E19/E20 -> 0 | F24: =F19/F20 -> 0 | G24: =G19/G20 -> 0 | H24: 0.25
A26: 債券残高(簿価) | B26: ='インプット'!C3 -> 0 | C26: =B26-C10+C14 -> 0 | D26: =C26-D10+D14 -> 0 | E26: =D26-E10+E14 -> 0 | F26: =E26-F10+F14 -> 0 | G26: =F26-G10+G14 -> 0
A27: 株式残高(簿価) | B27: ='インプット'!C4 -> 0 | C27: =B27-C11+C15 -> 0 | D27: =C27-D11+D15 -> 0 | E27: =D27-E11+E15 -> 0 | F27: =E27-F11+F15 -> 0 | G27: =F27-G11+G15 -> 0
A28: ﾌﾟﾗｲﾍﾞｰﾄ(簿価) | B28: ='インプット'!C5 -> 0 | C28: =B28+C13 -> 0 | D28: =C28+D13 -> 0 | E28: =D28+E13 -> 0 | F28: =E28+F13 -> 0 | G28: =F28+G13 -> 0
A29: 合計(簿価) | B29: =B26+B27+B28 -> 0 | C29: =C26+C27+C28 -> 0 | D29: =D26+D27+D28 -> 0 | E29: =E26+E27+E28 -> 0 | F29: =F26+F27+F28 -> 0 | G29: =G26+G27+G28 -> 0
A31: 評価損益(債券) | B31: 0 | C31: =C17-C26 -> 0 | D31: =D17-D26 -> 0 | E31: =E17-E26 -> 0 | F31: =F17-F26 -> 0 | G31: =G17-G26 -> 0
A32: 評価損益(株式) | B32: 0 | C32: =C18-C27 -> 0 | D32: =D18-D27 -> 0 | E32: =E18-E27 -> 0 | F32: =F18-F27 -> 0 | G32: =G18-G27 -> 0

Sheet Base
A1: ■ Base(中央) シミュレーション
A2: 配分比率(オレンジ枠)を変更可。リターンはインプットシートから自動計算。
A3: 株式配分比率 ← 変更可 | C3: 1 | D3: 1 | E3: 1 | F3: 1 | G3: 1
A4: 債券配分比率 | C4: =1-C3 -> 0 | D4: =1-D3 -> 0 | E4: =1-E3 -> 0 | F4: =1-F3 -> 0 | G4: =1-G3 -> 0
A6: 債券期待ﾘﾀｰﾝ(自動) | C6: ='インプット'!B98 -> 0 | D6: ='インプット'!C98 -> 0 | E6: ='インプット'!D98 -> 0 | F6: ='インプット'!E98 -> 0 | G6: ='インプット'!F98 -> 0
A7: 株式期待ﾘﾀｰﾝ(自動) | C7: ='インプット'!B99 -> 0 | D7: ='インプット'!C99 -> 0 | E7: ='インプット'!D99 -> 0 | F7: ='インプット'!E99 -> 0 | G7: ='インプット'!F99 -> 0
B9: 現状 | C9: 2026 | D9: 2027 | E9: 2028 | F9: 2029 | G9: 2030 | H9: 目標
A10: 債券償還(簿価) | B10: 0 | C10: ='インプット'!B15 -> 0 | D10: ='インプット'!C15 -> 0 | E10: ='インプット'!D15 -> 0 | F10: ='インプット'!E15 -> 0 | G10: ='インプット'!F15 -> 0
A11: 株式償還 | B11: 0 | C11: ='インプット'!B16 -> 0 | D11: ='インプット'!C16 -> 0 | E11: ='インプット'!D16 -> 0 | F11: ='インプット'!E16 -> 0 | G11: ='インプット'!F16 -> 0
A12: 伝統資産投資 | B12: 0 | C12: ='インプット'!B20 -> 0 | D12: ='インプット'!C20 -> 0 | E12: ='インプット'!D20 -> 0 | F12: ='インプット'!E20 -> 0 | G12: ='インプット'!F20 -> 0
A13: ﾌﾟﾗｲﾍﾞｰﾄ投資 | B13: 0 | C13: ='インプット'!B21 -> 0 | D13: ='インプット'!C21 -> 0 | E13: ='インプット'!D21 -> 0 | F13: ='インプット'!E21 -> 0 | G13: ='インプット'!F21 -> 0
A14: → 債券投資 | B14: 0 | C14: =C12*(1-C3) -> 0 | D14: =D12*(1-D3) -> 0 | E14: =E12*(1-E3) -> 0 | F14: =F12*(1-F3) -> 0 | G14: =G12*(1-G3) -> 0
A15: → 株式投資 | B15: 0 | C15: =C12*C3 -> 0 | D15: =D12*D3 -> 0 | E15: =E12*E3 -> 0 | F15: =F12*F3 -> 0 | G15: =G12*G3 -> 0
A17: 債券残高(時価) | B17: ='インプット'!B3 -> 0 | C17: =(B17-C10)*(1+C6)+C14 -> 0 | D17: =(C17-D10)*(1+D6)+D14 -> 0 | E17: =(D17-E10)*(1+E6)+E14 -> 0 | F17: =(E17-F10)*(1+F6)+F14 -> 0 | G17: =(F17-G10)*(1+G6)+G14 -> 0
A18: 株式残高(時価) | B18: ='インプット'!B4 -> 0 | C18: =(B18-C11)*(1+C7)+C15 -> 0 | D18: =(C18-D11)*(1+D7)+D15 -> 0 | E18: =(D18-E11)*(1+E7)+E15 -> 0 | F18: =(E18-F11)*(1+F7)+F15 -> 0 | G18: =(F18-G11)*(1+G7)+G15 -> 0
A19: ﾌﾟﾗｲﾍﾞｰﾄ残高 | B19: ='インプット'!B5 -> 0 | C19: =B19+C13 -> 0 | D19: =C19+D13 -> 0 | E19: =D19+E13 -> 0 | F19: =E19+F13 -> 0 | G19: =F19+G13 -> 0
A20: 合計(時価) | B20: =B17+B18+B19 -> 0 | C20: =C17+C18+C19 -> 0 | D20: =D17+D18+D19 -> 0 | E20: =E17+E18+E19 -> 0 | F20: =F17+F18+F19 -> 0 | G20: =G17+G18+G19 -> 0
A22: 債券構成比 | B22: =B17/B20 -> 0 | C22: =C17/C20 -> 0 | D22: =D17/D20 -> 0 | E22: =E17/E20 -> 0 | F22: =F17/F20 -> 0 | G22: =G17/G20 -> 0 | H22: 0.45
A23: 株式構成比 | B23: =B18/B20 -> 0 | C23: =C18/C20 -> 0 | D23: =D18/D20 -> 0 | E23: =E18/E20 -> 0 | F23: =F18/F20 -> 0 | G23: =G18/G20 -> 0 | H23: 0.25
A24: ﾌﾟﾗｲﾍﾞｰﾄ構成比 | B24: =B19/B20 -> 0 | C24: =C19/C20 -> 0 | D24: =D19/D20 -> 0 | E24: =E19/E20 -> 0 | F24: =F19/F20 -> 0 | G24: =G19/G20 -> 0 | H24: 0.25
A26: 債券残高(簿価) | B26: ='インプット'!C3 -> 0 | C26: =B26-C10+C14 -> 0 | D26: =C26-D10+D14 -> 0 | E26: =D26-E10+E14 -> 0 | F26: =E26-F10+F14 -> 0 | G26: =F26-G10+G14 -> 0
A27: 株式残高(簿価) | B27: ='インプット'!C4 -> 0 | C27: =B27-C11+C15 -> 0 | D27: =C27-D11+D15 -> 0 | E27: =D27-E11+E15 -> 0 | F27: =E27-F11+F15 -> 0 | G27: =F27-G11+G15 -> 0
A28: ﾌﾟﾗｲﾍﾞｰﾄ(簿価) | B28: ='インプット'!C5 -> 0 | C28: =B28+C13 -> 0 | D28: =C28+D13 -> 0 | E28: =D28+E13 -> 0 | F28: =E28+F13 -> 0 | G28: =F28+G13 -> 0
A29: 合計(簿価) | B29: =B26+B27+B28 -> 0 | C29: =C26+C27+C28 -> 0 | D29: =D26+D27+D28 -> 0 | E29: =E26+E27+E28 -> 0 | F29: =F26+F27+F28 -> 0 | G29: =G26+G27+G28 -> 0
A31: 評価損益(債券) | B31: 0 | C31: =C17-C26 -> 0 | D31: =D17-D26 -> 0 | E31: =E17-E26 -> 0 | F31: =F17-F26 -> 0 | G31: =G17-G26 -> 0
A32: 評価損益(株式) | B32: 0 | C32: =C18-C27 -> 0 | D32: =D18-D27 -> 0 | E32: =E18-E27 -> 0 | F32: =F18-F27 -> 0 | G32: =G18-G27 -> 0

Sheet Bear
A1: ■ Bear(悲観) シミュレーション
A2: 配分比率(オレンジ枠)を変更可。リターンはインプットシートから自動計算。
A3: 株式配分比率 ← 変更可 | C3: 0.31 | D3: 1 | E3: 1 | F3: 1 | G3: 1
A4: 債券配分比率 | C4: =1-C3 -> 0 | D4: =1-D3 -> 0 | E4: =1-E3 -> 0 | F4: =1-F3 -> 0 | G4: =1-G3 -> 0
A6: 債券期待ﾘﾀｰﾝ(自動) | C6: ='インプット'!B111 -> 0 | D6: ='インプット'!C111 -> 0 | E6: ='インプット'!D111 -> 0 | F6: ='インプット'!E111 -> 0 | G6: ='インプット'!F111 -> 0
A7: 株式期待ﾘﾀｰﾝ(自動) | C7: ='インプット'!B112 -> 0 | D7: ='インプット'!C112 -> 0 | E7: ='インプット'!D112 -> 0 | F7: ='インプット'!E112 -> 0 | G7: ='インプット'!F112 -> 0
B9: 現状 | C9: 2026 | D9: 2027 | E9: 2028 | F9: 2029 | G9: 2030 | H9: 目標
A10: 債券償還(簿価) | B10: 0 | C10: ='インプット'!B15 -> 0 | D10: ='インプット'!C15 -> 0 | E10: ='インプット'!D15 -> 0 | F10: ='インプット'!E15 -> 0 | G10: ='インプット'!F15 -> 0
A11: 株式償還 | B11: 0 | C11: ='インプット'!B16 -> 0 | D11: ='インプット'!C16 -> 0 | E11: ='インプット'!D16 -> 0 | F11: ='インプット'!E16 -> 0 | G11: ='インプット'!F16 -> 0
A12: 伝統資産投資 | B12: 0 | C12: ='インプット'!B20 -> 0 | D12: ='インプット'!C20 -> 0 | E12: ='インプット'!D20 -> 0 | F12: ='インプット'!E20 -> 0 | G12: ='インプット'!F20 -> 0
A13: ﾌﾟﾗｲﾍﾞｰﾄ投資 | B13: 0 | C13: ='インプット'!B21 -> 0 | D13: ='インプット'!C21 -> 0 | E13: ='インプット'!D21 -> 0 | F13: ='インプット'!E21 -> 0 | G13: ='インプット'!F21 -> 0
A14: → 債券投資 | B14: 0 | C14: =C12*(1-C3) -> 0 | D14: =D12*(1-D3) -> 0 | E14: =E12*(1-E3) -> 0 | F14: =F12*(1-F3) -> 0 | G14: =G12*(1-G3) -> 0
A15: → 株式投資 | B15: 0 | C15: =C12*C3 -> 0 | D15: =D12*D3 -> 0 | E15: =E12*E3 -> 0 | F15: =F12*F3 -> 0 | G15: =G12*G3 -> 0
A17: 債券残高(時価) | B17: ='インプット'!B3 -> 0 | C17: =(B17-C10)*(1+C6)+C14 -> 0 | D17: =(C17-D10)*(1+D6)+D14 -> 0 | E17: =(D17-E10)*(1+E6)+E14 -> 0 | F17: =(E17-F10)*(1+F6)+F14 -> 0 | G17: =(F17-G10)*(1+G6)+G14 -> 0
A18: 株式残高(時価) | B18: ='インプット'!B4 -> 0 | C18: =(B18-C11)*(1+C7)+C15 -> 0 | D18: =(C18-D11)*(1+D7)+D15 -> 0 | E18: =(D18-E11)*(1+E7)+E15 -> 0 | F18: =(E18-F11)*(1+F7)+F15 -> 0 | G18: =(F18-G11)*(1+G7)+G15 -> 0
A19: ﾌﾟﾗｲﾍﾞｰﾄ残高 | B19: ='インプット'!B5 -> 0 | C19: =B19+C13 -> 0 | D19: =C19+D13 -> 0 | E19: =D19+E13 -> 0 | F19: =E19+F13 -> 0 | G19: =F19+G13 -> 0
A20: 合計(時価) | B20: =B17+B18+B19 -> 0 | C20: =C17+C18+C19 -> 0 | D20: =D17+D18+D19 -> 0 | E20: =E17+E18+E19 -> 0 | F20: =F17+F18+F19 -> 0 | G20: =G17+G18+G19 -> 0
A22: 債券構成比 | B22: =B17/B20 -> 0 | C22: =C17/C20 -> 0 | D22: =D17/D20 -> 0 | E22: =E17/E20 -> 0 | F22: =F17/F20 -> 0 | G22: =G17/G20 -> 0 | H22: 0.45
A23: 株式構成比 | B23: =B18/B20 -> 0 | C23: =C18/C20 -> 0 | D23: =D18/D20 -> 0 | E23: =E18/E20 -> 0 | F23: =F18/F20 -> 0 | G23: =G18/G20 -> 0 | H23: 0.25
A24: ﾌﾟﾗｲﾍﾞｰﾄ構成比 | B24: =B19/B20 -> 0 | C24: =C19/C20 -> 0 | D24: =D19/D20 -> 0 | E24: =E19/E20 -> 0 | F24: =F19/F20 -> 0 | G24: =G19/G20 -> 0 | H24: 0.25
A26: 債券残高(簿価) | B26: ='インプット'!C3 -> 0 | C26: =B26-C10+C14 -> 0 | D26: =C26-D10+D14 -> 0 | E26: =D26-E10+E14 -> 0 | F26: =E26-F10+F14 -> 0 | G26: =F26-G10+G14 -> 0
A27: 株式残高(簿価) | B27: ='インプット'!C4 -> 0 | C27: =B27-C11+C15 -> 0 | D27: =C27-D11+D15 -> 0 | E27: =D27-E11+E15 -> 0 | F27: =E27-F11+F15 -> 0 | G27: =F27-G11+G15 -> 0
A28: ﾌﾟﾗｲﾍﾞｰﾄ(簿価) | B28: ='インプット'!C5 -> 0 | C28: =B28+C13 -> 0 | D28: =C28+D13 -> 0 | E28: =D28+E13 -> 0 | F28: =E28+F13 -> 0 | G28: =F28+G13 -> 0
A29: 合計(簿価) | B29: =B26+B27+B28 -> 0 | C29: =C26+C27+C28 -> 0 | D29: =D26+D27+D28 -> 0 | E29: =E26+E27+E28 -> 0 | F29: =F26+F27+F28 -> 0 | G29: =G26+G27+G28 -> 0
A31: 評価損益(債券) | B31: 0 | C31: =C17-C26 -> 0 | D31: =D17-D26 -> 0 | E31: =E17-E26 -> 0 | F31: =F17-F26 -> 0 | G31: =G17-G26 -> 0
A32: 評価損益(株式) | B32: 0 | C32: =C18-C27 -> 0 | D32: =D18-D27 -> 0 | E32: =E18-E27 -> 0 | F32: =F18-F27 -> 0 | G32: =G18-G27 -> 0
