Workbook

Sheet 1. インプット
A1: 信連用 経営インパクトシミュレーターインプット
A3: 1.1 初期データ（現状） | F3: 1.2 環境シナリオと経営アクション
A5: カテゴリ | B5: 項目 | C5: 値 | D5: 単位/説明 | F5: カテゴリ | G5: 項目 | H5: 値 | I5: 単位/説明
A6: 貸借対照表（資産） | B6: 農林中金預け金（必須分） | C6: 27666 | D6: 億円 | F6: 環境シナリオ（外部要因）
B7: 農林中金預け金（任意分） | C7: 2618 | D7: 億円 | F7: マクロ環境 | G7: 貯金流出率（年率） | H7: 0 | I7: %
B8: 有価証券残高 | C8: 13557 | D8: 億円 | G8: 市場金利変化幅 (ΔRate) | H8: 0 | I8: %
B9: 貸出金残高 | C9: 11447 | D9: 億円 | F9: 市場金利連動率（β値） | G9: 貯金金利連動率 | H9: 1 | I9: 倍
B10: その他資産 | C10: 5476 | D10: 億円 | G10: 農中預け金連動率（必須分） | H10: 1 | I10: 倍
A11: 貸借対照表（負債・純資産） | B11: 貯金残高 | C11: 55332 | D11: 億円 | G11: 農中預け金連動率（任意分） | H11: 1 | I11: 倍
A12: 健全性指標 | B12: 自己資本（比率分子） | C12: 4484 | D12: 億円 | G12: 貸出金利連動率 | H12: 0.6 | I12: 倍
B13: その他有価証券評価差額金（AOCI） | C13: -263 | D13: 億円 | F13: 経営アクション（内部要因）
A14: 損益計算書 | B14: 経費（絶対額） | C14: 49 | D14: 億円 | F14: 有価証券・ALM戦略 | G14: 1. リスクテイク: 利回り向上 (bps) | H14: 0 | I14: bps
B15: 与信コスト（絶対額） | C15: 10 | D15: 億円 | G15: 2. ALM: アセットスワップ活用比率 (%) | H15: 0 | I15: %
B16: その他収支（絶対額） | C16: 52 | D16: 億円 | G16: 3. 構造: HTM比率目標 (%) | H16: 20 | I16: %
A17: 主要な利回り・コスト | B17: 農林中金預け金利回り（必須分） | C17: 0.724 | D17: % | G17: 4. 目標有価証券デュレーション（年） | H17: 5 | I17: 年
B18: 農林中金預け金利回り（任意分） | C18: 0.1 | D18: % | F18: 資産アロケーション戦略 | G18: 5. 貸出金比率目標 (%) | H18: 41.441605 | I18: %
B19: 有価証券利回り | C19: 1.02 | D19: % | G19: 6. 有価証券比率目標 (%) | H19: 49.080443 | I19: %
B20: 貸出金利回り | C20: 0.51 | D20: % | G20: → 農林中金（任意分）比率 | H20: =MAX(0, 100 - '1. インプット'!H18 - '1. インプット'!H19) -> 9.4779524 | I20: % (自動計算)
B21: 貯金利回り（平均） | C21: 0.57 | D21: % | F21: コスト・収益多角化戦略 | G21: 7. 経費変化率 (%) | H21: 0 | I21: %
A22: その他パラメータ | B22: 有価証券デュレーション | C22: 5 | D22: 年 | G22: 8. 役務収益等変化率 (%) | H22: 0 | I22: %
A23: リスクウェイト（RW） | B23: RW_預け金（%） | C23: 21 | D23: % | G23: 9. 貸出プライシング: スプレッド変化 (bps) | H23: 0 | I23: bps
B24: RW_有価証券（%） | C24: 85 | D24: %
B25: RW_貸出金（%） | C25: 85 | D25: %
B26: RW_その他資産（%） | C26: 56.94 | D26: %
A27: その他パラメータ | B27: 固定RWA（億円） | C27: 2783 | D27: 億円
B28: 実効税率（%） | C28: 17.8 | D28: %
B29: 目標当期純利益 | C29: 70 | D29: 億円

Sheet 2. 計算ロジック
A1: >>>計算ロジック
A3: >＞定数定義
A4: 必須預け金比率 | B4: 0.5 | C4: NORINCHUKIN_MANDATORY_RATIO
A5: LCR AFSヘアカット率 | B5: 0.15 | C5: LCR_HQLA_HAIRCUT_AFS
A6: LCR 純資金流出率 | B6: 0.05 | C6: LCR_NET_OUTFLOW_RATIO
A7: リスクテイクRWA影響度 | B7: 50 | C7: RISK_TAKING_RWA_IMPACT_FACTOR
A8: 許容誤差（ゼロ除算回避用） | B8: 1e-09 | C8: TOLERANCE
A11: >＞インプットデータを計算用に転記
A12: >初期データ (Base)
A13: 貯金残高 | B13: ='1. インプット'!C11 -> 55332 | C13: (億円)
A14: 有価証券残高 | B14: ='1. インプット'!C8 -> 13557 | C14: (億円)
A15: 貸出金残高 | B15: ='1. インプット'!C9 -> 11447 | C15: (億円)
A16: 農林中金預け金（必須分） | B16: ='1. インプット'!C6 -> 27666 | C16: (億円)
A17: 農林中金預け金（任意分） | B17: ='1. インプット'!C7 -> 2618 | C17: (億円)
A18: その他資産 | B18: ='1. インプット'!C10 -> 5476 | C18: (億円)
A19: 自己資本（比率分子） | B19: ='1. インプット'!C12 -> 4484 | C19: (億円)
A20: その他有価証券評価差額金（AOCI） | B20: ='1. インプット'!C13 -> -263 | C20: (億円)
A21: 経費（絶対額） | B21: ='1. インプット'!C14 -> 49 | C21: (億円)
A22: 与信コスト（絶対額） | B22: ='1. インプット'!C15 -> 10 | C22: (億円)
A23: その他収支（絶対額） | B23: ='1. インプット'!C16 -> 52 | C23: (億円)
A24: 目標当期純利益 | B24: ='1. インプット'!C29 -> 70 | C24: (億円)
A25: 農林中金預け金利回り（必須分） | B25: ='1. インプット'!C17 / 100 -> 0.00724 | C25: (比率)
A26: 農林中金預け金利回り（任意分） | B26: ='1. インプット'!C18 / 100 -> 0.001 | C26: (比率)
A27: 有価証券利回り | B27: ='1. インプット'!C19 / 100 -> 0.0102 | C27: (比率)
A28: 貸出金利回り | B28: ='1. インプット'!C20 / 100 -> 0.0051 | C28: (比率)
A29: 貯金利回り（平均） | B29: ='1. インプット'!C21 / 100 -> 0.0057 | C29: (比率)
A30: 有価証券デュレーション | B30: ='1. インプット'!C22 -> 5 | C30: (年)
A31: 実効税率（%） | B31: ='1. インプット'!C28 / 100 -> 0.178 | C31: (比率)
A32: RW_預け金（%） | B32: ='1. インプット'!C23 / 100 -> 0.21 | C32: (比率)
A33: RW_有価証券（%） | B33: ='1. インプット'!C24 / 100 -> 0.85 | C33: (比率)
A34: RW_貸出金（%） | B34: ='1. インプット'!C25 / 100 -> 0.85 | C34: (比率)
A35: RW_その他資産（%） | B35: ='1. インプット'!C26 / 100 -> 0.5694 | C35: (比率)
A36: 固定RWA（億円） | B36: ='1. インプット'!C27 -> 2783 | C36: (億円)
A38: >>シナリオパラメータ (Scenario)
A39: 貯金流出率（年率） | B39: ='1. インプット'!H7 / 100 -> 0 | C39: (比率)
A40: 市場金利変化幅 (ΔRate) | B40: ='1. インプット'!H8 / 100 -> 0 | C40: (比率)
A41: 貯金金利連動率 | B41: ='1. インプット'!H9 -> 1 | C41: (倍)
A42: 農中預け金連動率（必須分） | B42: ='1. インプット'!H10 -> 1 | C42: (倍)
A43: 農中預け金連動率（任意分） | B43: ='1. インプット'!H11 -> 1 | C43: (倍)
A44: 貸出金利連動率 | B44: ='1. インプット'!H12 -> 0.6 | C44: (倍)
...

Sheet 3. 結果サマリー
A1: シミュレーション結果サマリー
A3: 1. KPIサマリー
A5: カテゴリ | B5: 指標 | C5: 現状 | D5: シナリオ後 | E5: 変化量 | F5: 単位
A6: 目標達成度 | B6: 当期純利益 | C6: ='2. 計算ロジック'!B61 -> 63.44898 | D6: ='2. 計算ロジック'!B116 -> 63.44898 | E6: =ROUND(D6 - C6, 5) -> 0 | F6: 億円
B7: ROE (会計ベース) | C7: ='2. 計算ロジック'!B70 -> 1.5031741 | D7: ='2. 計算ロジック'!B132 -> 1.5031741 | E7: =ROUND(D7 - C7, 5) -> 0 | F7: %
A8: 収益性 | B8: 資金利益 (NII) | C8: ='2. 計算ロジック'!B59 -> 84.18854 | D8: ='2. 計算ロジック'!B110 -> 84.18854 | E8: =ROUND(D8 - C8, 5) -> 0 | F8: 億円
B9: NIM | C9: ='2. 計算ロジック'!B71 -> 0.15227272 | D9: ='2. 計算ロジック'!B133 -> 0.15227272 | E9: =ROUND(D9 - C9, 5) -> 0 | F9: %
A10: 健全性 | B10: 自己資本比率 (対RWA) | C10: ='2. 計算ロジック'!B72 -> 13.379453 | D10: ='2. 計算ロジック'!B134 -> 13.379453 | E10: =ROUND(D10 - C10, 5) -> 0 | F10: %
B11: 評価損益 (AOCI) | C11: ='2. 計算ロジック'!B20 -> -263 | D11: ='2. 計算ロジック'!B118 -> -263 | E11: =ROUND(D11 - C11, 5) -> 0 | F11: 億円
A12: 流動性 | B12: LCR (簡易試算) | C12: ='2. 計算ロジック'!B80 -> 501.319 | D12: ='2. 計算ロジック'!B142 -> 418.01494 | E12: =ROUND(D12 - C12, 5) -> -83.30406 | F12: %
B13: HQLA残高 | C13: ='2. 計算ロジック'!B78 -> 13869.491 | D13: ='2. 計算ロジック'!B140 -> 11564.801 | E13: =ROUND(D13 - C13, 5) -> -2304.69 | F13: 億円
A14: 規模 | B14: 総資産 | C14: ='2. 計算ロジック'!B67 -> 60764 | D14: ='2. 計算ロジック'!B129 -> 60764 | E14: =ROUND(D14 - C14, 5) -> 0 | F14: 億円
B15: RWA | C15: ='2. 計算ロジック'!B66 -> 33514.074 | D15: ='2. 計算ロジック'!B128 -> 33514.074 | E15: =ROUND(D15 - C15, 5) -> 0 | F15: 億円
A18: 2. 要因分析とバランスシート変化
A19: 2.1 資金利益(NII)変動の要因分析（億円） | H19: 2.2 バランスシート（資産サイド）の変化（億円）
A20: 現状NII | B20: =ROUND('2. 計算ロジック'!B146, 5) -> 84.18854 | H20: 項目 | I20: 現状 | J20: シナリオ後
A21: ボリューム効果 | B21: =ROUND('2. 計算ロジック'!B148, 5) -> 0 | H21: その他資産 | I21: ='2. 計算ロジック'!B18 -> 5476 | J21: ='2. 計算ロジック'!B18 -> 5476
A22: 市場金利変動 | B22: =ROUND('2. 計算ロジック'!B155, 5) -> 0 | H22: 貸出金 | I22: ='2. 計算ロジック'!B15 -> 11447 | J22: ='2. 計算ロジック'!B90 -> 11447
A23: リスクテイク戦略 | B23: =ROUND('2. 計算ロジック'!B157, 5) -> 0 | H23: 有価証券(HTM) | I23: 0 | J23: ='2. 計算ロジック'!B93 -> 2711.4
A24: スワップ戦略 | B24: =ROUND('2. 計算ロジック'!B158, 5) -> 0 | H24: 有価証券(AFS/その他) | I24: ='2. 計算ロジック'!B14 -> 13557 | J24: ='2. 計算ロジック'!B94 -> 10845.6
A25: プライシング戦略 | B25: =ROUND('2. 計算ロジック'!B156, 5) -> 0 | H25: 任意預け金(農中) | I25: ='2. 計算ロジック'!B17 -> 2618 | J25: ='2. 計算ロジック'!B92 -> 2618
A26: 想定NII | B26: =ROUND('2. 計算ロジック'!B159, 5) -> 84.18854 | H26: 必須預け金(農中) | I26: ='2. 計算ロジック'!B16 -> 27666 | J26: ='2. 計算ロジック'!B85 -> 27666
H27: 総資産合計 | I27: =SUM(I21:I26) -> 60764 | J27: =SUM(J21:J26) -> 60764
I29: その他資産 | J29: 貸出金 | K29: 有価証券(HTM) | L29: 有価証券(AFS/その他) | M29: 任意預け金(農中) | N29: 必須預け金(農中)
H30: 現状 | I30: ='3. 結果サマリー'!I21 -> 5476 | J30: ='3. 結果サマリー'!I22 -> 11447 | K30: ='3. 結果サマリー'!I23 -> 0 | L30: ='3. 結果サマリー'!I24 -> 13557 | M30: ='3. 結果サマリー'!I25 -> 2618 | N30: ='3. 結果サマリー'!I26 -> 27666
H31: シナリオ後 | I31: ='3. 結果サマリー'!J21 -> 5476 | J31: ='3. 結果サマリー'!J22 -> 11447 | K31: ='3. 結果サマリー'!J23 -> 2711.4 | L31: ='3. 結果サマリー'!J24 -> 10845.6 | M31: ='3. 結果サマリー'!J25 -> 2618 | N31: ='3. 結果サマリー'!J26 -> 27666
A60: 3. 戦略的意思決定の示唆（感応度分析：データテーブル）
A63: 3.1 HTM戦略（資本安定性 vs 流動性） | H63: 3.2 リスクテイク戦略（収益性 vs 健全性）
A64: HTM比率(%) | B64: LCR (%) | C64: AOCI (億円) | H64: 利回り向上幅(bps) | I64: NII (億円) | J64: 自己資本比率 (%)
A65: 0 | B65: ='2. 計算ロジック'!B142 -> 418.01494 | C65: ='2. 計算ロジック'!B118 -> -263 | H65: 0 | I65: ='2. 計算ロジック'!B110 -> 84.18854 | J65: ='2. 計算ロジック'!B134 -> 13.379453
A66: 10 | H66: 20
A67: 20 | H67: 40
A68: 30 | H68: 60
A69: 40 | H69: 80
A70: 50 | H70: 100
A71: 60 | H71: 120
A72: 70 | H72: 140
A73: 80 | H73: 160
A74: 90 | H74: 180
A75: 100 | H75: 200
...
